iteration_with_fail_part2 error at node_count 41, edge_count: 525
error: RunError { error: InternalError("bug: NodeInfo { job_id: \"N4\", state: Output(FinishedUpstreamFailure), history_output: None, last_considered_in_gen: 8 }") }
Jobs: N0(0): Always(Undetermined)
N1(1): Ephemeral(NotReady(Unknown))
N2(2): Ephemeral(NotReady(Unknown))
N3(3): Ephemeral(NotReady(Unknown))
N4(4): Output(NotReady(Unknown))


Edges:
(N0(0)->N1(1): Unknown
(N1(1)->N4(4): Unknown
(N2(2)->N3(3): Unknown
(N3(3)->N4(4): Unknown


in code: 
g.add_node("N0", JobKind::Always);
g.add_node("N1", JobKind::Ephemeral);
g.add_node("N2", JobKind::Ephemeral);
g.add_node("N3", JobKind::Ephemeral);
g.add_node("N4", JobKind::Output);
let edges = vec![
("N1", "N0"), 
("N4", "N1"), 
("N3", "N2"), 
("N4", "N3"), 
];
for (a,b) in edges {
            if g.contains_node(a) && g.contains_node(b){
                g.depends_on(a,b);
            }
        }
        ["N0"]